Watching for file changes with StatReloader
Performing system checks...

System check identified no issues (0 silenced).
March 27, 2025 - 02:13:50
Django version 5.1.4, using settings 'mysite.settings'
Starting development server at http://127.0.0.1:8081/
Quit the server with CONTROL-C.

Watching for file changes with StatReloader
Session data corrupted
Internal Server Error: /.well-known/microsoft-identity-association
Traceback (most recent call last):
  File "/root/.pyenv/versions/mj-313/lib/python3.13/site-packages/django/core/handlers/exception.py", line 55, in inner
    response = get_response(request)
  File "/root/.pyenv/versions/mj-313/lib/python3.13/site-packages/django/core/handlers/base.py", line 197, in _get_response
    response = wrapped_callback(request, *callback_args, **callback_kwargs)
TypeError: microsoft_id_api() missing 1 required keyword-only argument: 'context'
[27/Mar/2025 02:14:30] "GET /.well-known/microsoft-identity-association HTTP/1.0" 500 60726
Not Found: /wp-admin/setup-config.php
[27/Mar/2025 02:15:49] "GET /wp-admin/setup-config.php HTTP/1.0" 404 3464
Watching for file changes with StatReloader
Error: That port is already in use.
Session data corrupted
Internal Server Error: /.well-known/microsoft-identity-association
Traceback (most recent call last):
  File "/root/.pyenv/versions/mj-313/lib/python3.13/site-packages/django/core/handlers/exception.py", line 55, in inner
    response = get_response(request)
  File "/root/.pyenv/versions/mj-313/lib/python3.13/site-packages/django/core/handlers/base.py", line 197, in _get_response
    response = wrapped_callback(request, *callback_args, **callback_kwargs)
TypeError: microsoft_id_api() missing 1 required keyword-only argument: 'context'
[27/Mar/2025 02:17:00] "GET /.well-known/microsoft-identity-association HTTP/1.0" 500 60726
/root/login-pro/mysite/views.py changed, reloading.
Performing system checks...

System check identified no issues (0 silenced).
March 27, 2025 - 02:14:26
Django version 5.1.4, using settings 'mysite.settings'
Starting development server at http://127.0.0.1:8081/
Quit the server with CONTROL-C.

Watching for file changes with StatReloader
Invalid HTTP_HOST header: '121.40.149.206'. You may need to add '121.40.149.206' to ALLOWED_HOSTS.
Traceback (most recent call last):
  File "/root/.pyenv/versions/mj-313/lib/python3.13/site-packages/django/core/handlers/exception.py", line 55, in inner
    response = get_response(request)
  File "/root/.pyenv/versions/mj-313/lib/python3.13/site-packages/django/utils/deprecation.py", line 128, in __call__
    response = self.process_request(request)
  File "/root/.pyenv/versions/mj-313/lib/python3.13/site-packages/django/middleware/common.py", line 48, in process_request
    host = request.get_host()
  File "/root/.pyenv/versions/mj-313/lib/python3.13/site-packages/django/http/request.py", line 151, in get_host
    raise DisallowedHost(msg)
django.core.exceptions.DisallowedHost: Invalid HTTP_HOST header: '121.40.149.206'. You may need to add '121.40.149.206' to ALLOWED_HOSTS.
Bad Request: /
[27/Mar/2025 02:17:44] "GET / HTTP/1.0" 400 66603
/root/login-pro/mysite/views.py changed, reloading.
Performing system checks...

System check identified no issues (0 silenced).
March 27, 2025 - 02:17:39
Django version 5.1.4, using settings 'mysite.settings'
Starting development server at http://127.0.0.1:8081/
Quit the server with CONTROL-C.

Watching for file changes with StatReloader
Exception in thread django-main-thread:
Traceback (most recent call last):
  File "/root/.pyenv/versions/3.13.0/lib/python3.13/threading.py", line 1041, in _bootstrap_inner
    self.run()
    ~~~~~~~~^^
  File "/root/.pyenv/versions/3.13.0/lib/python3.13/threading.py", line 992, in run
    self._target(*self._args, **self._kwargs)
    ~~~~~~~~~~~~^^^^^^^^^^^^^^^^^^^^^^^^^^^^^
  File "/root/.pyenv/versions/mj-313/lib/python3.13/site-packages/django/utils/autoreload.py", line 64, in wrapper
    fn(*args, **kwargs)
    ~~^^^^^^^^^^^^^^^^^
  File "/root/.pyenv/versions/mj-313/lib/python3.13/site-packages/django/core/management/commands/runserver.py", line 134, in inner_run
    self.check(display_num_errors=True)
    ~~~~~~~~~~^^^^^^^^^^^^^^^^^^^^^^^^^
  File "/root/.pyenv/versions/mj-313/lib/python3.13/site-packages/django/core/management/base.py", line 486, in check
    all_issues = checks.run_checks(
        app_configs=app_configs,
    ...<2 lines>...
        databases=databases,
    )
  File "/root/.pyenv/versions/mj-313/lib/python3.13/site-packages/django/core/checks/registry.py", line 88, in run_checks
    new_errors = check(app_configs=app_configs, databases=databases)
  File "/root/.pyenv/versions/mj-313/lib/python3.13/site-packages/django/core/checks/urls.py", line 136, in check_custom_error_handlers
    handler = resolver.resolve_error_handler(status_code)
  File "/root/.pyenv/versions/mj-313/lib/python3.13/site-packages/django/urls/resolvers.py", line 732, in resolve_error_handler
    callback = getattr(self.urlconf_module, "handler%s" % view_type, None)
                       ^^^^^^^^^^^^^^^^^^^
  File "/root/.pyenv/versions/mj-313/lib/python3.13/site-packages/django/utils/functional.py", line 47, in __get__
    res = instance.__dict__[self.name] = self.func(instance)
                                         ~~~~~~~~~^^^^^^^^^^
  File "/root/.pyenv/versions/mj-313/lib/python3.13/site-packages/django/urls/resolvers.py", line 711, in urlconf_module
    return import_module(self.urlconf_name)
  File "/root/.pyenv/versions/3.13.0/lib/python3.13/importlib/__init__.py", line 88, in import_module
    return _bootstrap._gcd_import(name[level:], package, level)
           ~~~~~~~~~~~~~~~~~~~~~~^^^^^^^^^^^^^^^^^^^^^^^^^^^^^^
  File "<frozen importlib._bootstrap>", line 1387, in _gcd_import
  File "<frozen importlib._bootstrap>", line 1360, in _find_and_load
  File "<frozen importlib._bootstrap>", line 1331, in _find_and_load_unlocked
  File "<frozen importlib._bootstrap>", line 935, in _load_unlocked
  File "<frozen importlib._bootstrap_external>", line 1022, in exec_module
  File "<frozen importlib._bootstrap>", line 488, in _call_with_frames_removed
  File "/root/login-pro/mysite/urls.py", line 21, in <module>
    from . import views
  File "/root/login-pro/mysite/views.py", line 33
    def microsoft_id_api(request, *):
                                  ^
SyntaxError: named arguments must follow bare *
/root/login-pro/mysite/views.py changed, reloading.
Performing system checks...

Watching for file changes with StatReloader
Exception in thread django-main-thread:
Traceback (most recent call last):
  File "/root/.pyenv/versions/3.13.0/lib/python3.13/threading.py", line 1041, in _bootstrap_inner
    self.run()
    ~~~~~~~~^^
  File "/root/.pyenv/versions/3.13.0/lib/python3.13/threading.py", line 992, in run
    self._target(*self._args, **self._kwargs)
    ~~~~~~~~~~~~^^^^^^^^^^^^^^^^^^^^^^^^^^^^^
  File "/root/.pyenv/versions/mj-313/lib/python3.13/site-packages/django/utils/autoreload.py", line 64, in wrapper
    fn(*args, **kwargs)
    ~~^^^^^^^^^^^^^^^^^
  File "/root/.pyenv/versions/mj-313/lib/python3.13/site-packages/django/core/management/commands/runserver.py", line 134, in inner_run
    self.check(display_num_errors=True)
    ~~~~~~~~~~^^^^^^^^^^^^^^^^^^^^^^^^^
  File "/root/.pyenv/versions/mj-313/lib/python3.13/site-packages/django/core/management/base.py", line 486, in check
    all_issues = checks.run_checks(
        app_configs=app_configs,
    ...<2 lines>...
        databases=databases,
    )
  File "/root/.pyenv/versions/mj-313/lib/python3.13/site-packages/django/core/checks/registry.py", line 88, in run_checks
    new_errors = check(app_configs=app_configs, databases=databases)
  File "/root/.pyenv/versions/mj-313/lib/python3.13/site-packages/django/core/checks/urls.py", line 136, in check_custom_error_handlers
    handler = resolver.resolve_error_handler(status_code)
  File "/root/.pyenv/versions/mj-313/lib/python3.13/site-packages/django/urls/resolvers.py", line 732, in resolve_error_handler
    callback = getattr(self.urlconf_module, "handler%s" % view_type, None)
                       ^^^^^^^^^^^^^^^^^^^
  File "/root/.pyenv/versions/mj-313/lib/python3.13/site-packages/django/utils/functional.py", line 47, in __get__
    res = instance.__dict__[self.name] = self.func(instance)
                                         ~~~~~~~~~^^^^^^^^^^
  File "/root/.pyenv/versions/mj-313/lib/python3.13/site-packages/django/urls/resolvers.py", line 711, in urlconf_module
    return import_module(self.urlconf_name)
  File "/root/.pyenv/versions/3.13.0/lib/python3.13/importlib/__init__.py", line 88, in import_module
    return _bootstrap._gcd_import(name[level:], package, level)
           ~~~~~~~~~~~~~~~~~~~~~~^^^^^^^^^^^^^^^^^^^^^^^^^^^^^^
  File "<frozen importlib._bootstrap>", line 1387, in _gcd_import
  File "<frozen importlib._bootstrap>", line 1360, in _find_and_load
  File "<frozen importlib._bootstrap>", line 1331, in _find_and_load_unlocked
  File "<frozen importlib._bootstrap>", line 935, in _load_unlocked
  File "<frozen importlib._bootstrap_external>", line 1022, in exec_module
  File "<frozen importlib._bootstrap>", line 488, in _call_with_frames_removed
  File "/root/login-pro/mysite/urls.py", line 21, in <module>
    from . import views
  File "/root/login-pro/mysite/views.py", line 33
    def microsoft_id_api(request, *):
                                  ^
SyntaxError: named arguments must follow bare *
/root/login-pro/mysite/views.py changed, reloading.
Performing system checks...

Watching for file changes with StatReloader
Exception in thread django-main-thread:
Traceback (most recent call last):
  File "/root/.pyenv/versions/3.13.0/lib/python3.13/threading.py", line 1041, in _bootstrap_inner
    self.run()
    ~~~~~~~~^^
  File "/root/.pyenv/versions/3.13.0/lib/python3.13/threading.py", line 992, in run
    self._target(*self._args, **self._kwargs)
    ~~~~~~~~~~~~^^^^^^^^^^^^^^^^^^^^^^^^^^^^^
  File "/root/.pyenv/versions/mj-313/lib/python3.13/site-packages/django/utils/autoreload.py", line 64, in wrapper
    fn(*args, **kwargs)
    ~~^^^^^^^^^^^^^^^^^
  File "/root/.pyenv/versions/mj-313/lib/python3.13/site-packages/django/core/management/commands/runserver.py", line 134, in inner_run
    self.check(display_num_errors=True)
    ~~~~~~~~~~^^^^^^^^^^^^^^^^^^^^^^^^^
  File "/root/.pyenv/versions/mj-313/lib/python3.13/site-packages/django/core/management/base.py", line 486, in check
    all_issues = checks.run_checks(
        app_configs=app_configs,
    ...<2 lines>...
        databases=databases,
    )
  File "/root/.pyenv/versions/mj-313/lib/python3.13/site-packages/django/core/checks/registry.py", line 88, in run_checks
    new_errors = check(app_configs=app_configs, databases=databases)
  File "/root/.pyenv/versions/mj-313/lib/python3.13/site-packages/django/core/checks/urls.py", line 136, in check_custom_error_handlers
    handler = resolver.resolve_error_handler(status_code)
  File "/root/.pyenv/versions/mj-313/lib/python3.13/site-packages/django/urls/resolvers.py", line 732, in resolve_error_handler
    callback = getattr(self.urlconf_module, "handler%s" % view_type, None)
                       ^^^^^^^^^^^^^^^^^^^
  File "/root/.pyenv/versions/mj-313/lib/python3.13/site-packages/django/utils/functional.py", line 47, in __get__
    res = instance.__dict__[self.name] = self.func(instance)
                                         ~~~~~~~~~^^^^^^^^^^
  File "/root/.pyenv/versions/mj-313/lib/python3.13/site-packages/django/urls/resolvers.py", line 711, in urlconf_module
    return import_module(self.urlconf_name)
  File "/root/.pyenv/versions/3.13.0/lib/python3.13/importlib/__init__.py", line 88, in import_module
    return _bootstrap._gcd_import(name[level:], package, level)
           ~~~~~~~~~~~~~~~~~~~~~~^^^^^^^^^^^^^^^^^^^^^^^^^^^^^^
  File "<frozen importlib._bootstrap>", line 1387, in _gcd_import
  File "<frozen importlib._bootstrap>", line 1360, in _find_and_load
  File "<frozen importlib._bootstrap>", line 1331, in _find_and_load_unlocked
  File "<frozen importlib._bootstrap>", line 935, in _load_unlocked
  File "<frozen importlib._bootstrap_external>", line 1022, in exec_module
  File "<frozen importlib._bootstrap>", line 488, in _call_with_frames_removed
  File "/root/login-pro/mysite/urls.py", line 21, in <module>
    from . import views
  File "/root/login-pro/mysite/views.py", line 33
    def microsoft_id_api(request, *):
                                  ^
SyntaxError: named arguments must follow bare *
/root/login-pro/mysite/views.py changed, reloading.
Performing system checks...

Watching for file changes with StatReloader
Exception in thread django-main-thread:
Traceback (most recent call last):
  File "/root/.pyenv/versions/3.13.0/lib/python3.13/threading.py", line 1041, in _bootstrap_inner
    self.run()
    ~~~~~~~~^^
  File "/root/.pyenv/versions/3.13.0/lib/python3.13/threading.py", line 992, in run
    self._target(*self._args, **self._kwargs)
    ~~~~~~~~~~~~^^^^^^^^^^^^^^^^^^^^^^^^^^^^^
  File "/root/.pyenv/versions/mj-313/lib/python3.13/site-packages/django/utils/autoreload.py", line 64, in wrapper
    fn(*args, **kwargs)
    ~~^^^^^^^^^^^^^^^^^
  File "/root/.pyenv/versions/mj-313/lib/python3.13/site-packages/django/core/management/commands/runserver.py", line 134, in inner_run
    self.check(display_num_errors=True)
    ~~~~~~~~~~^^^^^^^^^^^^^^^^^^^^^^^^^
  File "/root/.pyenv/versions/mj-313/lib/python3.13/site-packages/django/core/management/base.py", line 486, in check
    all_issues = checks.run_checks(
        app_configs=app_configs,
    ...<2 lines>...
        databases=databases,
    )
  File "/root/.pyenv/versions/mj-313/lib/python3.13/site-packages/django/core/checks/registry.py", line 88, in run_checks
    new_errors = check(app_configs=app_configs, databases=databases)
  File "/root/.pyenv/versions/mj-313/lib/python3.13/site-packages/django/core/checks/urls.py", line 136, in check_custom_error_handlers
    handler = resolver.resolve_error_handler(status_code)
  File "/root/.pyenv/versions/mj-313/lib/python3.13/site-packages/django/urls/resolvers.py", line 732, in resolve_error_handler
    callback = getattr(self.urlconf_module, "handler%s" % view_type, None)
                       ^^^^^^^^^^^^^^^^^^^
  File "/root/.pyenv/versions/mj-313/lib/python3.13/site-packages/django/utils/functional.py", line 47, in __get__
    res = instance.__dict__[self.name] = self.func(instance)
                                         ~~~~~~~~~^^^^^^^^^^
  File "/root/.pyenv/versions/mj-313/lib/python3.13/site-packages/django/urls/resolvers.py", line 711, in urlconf_module
    return import_module(self.urlconf_name)
  File "/root/.pyenv/versions/3.13.0/lib/python3.13/importlib/__init__.py", line 88, in import_module
    return _bootstrap._gcd_import(name[level:], package, level)
           ~~~~~~~~~~~~~~~~~~~~~~^^^^^^^^^^^^^^^^^^^^^^^^^^^^^^
  File "<frozen importlib._bootstrap>", line 1387, in _gcd_import
  File "<frozen importlib._bootstrap>", line 1360, in _find_and_load
  File "<frozen importlib._bootstrap>", line 1331, in _find_and_load_unlocked
  File "<frozen importlib._bootstrap>", line 935, in _load_unlocked
  File "<frozen importlib._bootstrap_external>", line 1022, in exec_module
  File "<frozen importlib._bootstrap>", line 488, in _call_with_frames_removed
  File "/root/login-pro/mysite/urls.py", line 21, in <module>
    from . import views
  File "/root/login-pro/mysite/views.py", line 34
    def microsoft_id_api(request, *):
                                  ^
SyntaxError: named arguments must follow bare *
